2025-03-11 17:44:28,733 - MainThread - sqlmesh.core.console - WARNING - The snowflake engine is not recommended for storing SQLMesh state in production deployments. Please see https://sqlmesh.readthedocs.io/en/stable/guides/configuration/#state-connection for a list of recommended engines and more information. (console.py:1269)
2025-03-11 17:44:28,750 - MainThread - snowflake.connector.connection - INFO - Snowflake Connector for Python Version: 3.14.0, Python Version: 3.11.9, Platform: Windows-10-10.0.22621-SP0 (connection.py:423)
2025-03-11 17:44:28,750 - MainThread - snowflake.connector.connection - INFO - Connecting to GLOBAL Snowflake domain (connection.py:1226)
2025-03-11 17:44:28,751 - MainThread - snowflake.connector.connection - INFO - This connection is in OCSP Fail Open Mode. TLS Certificates would be checked for validity and revocation status. Any other Certificate Revocation related exceptions or OCSP Responder failures would be disregarded in favor of connectivity. (connection.py:1315)
2025-03-11 17:44:33,145 - event-emitter - sqlmesh.core.analytics.dispatcher - INFO - Failed to emit events: HTTPSConnectionPool(host='analytics.tobikodata.com', port=443): Max retries exceeded with url: /v1/sqlmesh/ (Caused by SSLError(SSLCertVerificationError(1, '[SSL: CERTIFICATE_VERIFY_FAILED] certificate verify failed: self-signed certificate in certificate chain (_ssl.c:1006)'))) (dispatcher.py:138)
2025-03-11 17:44:38,266 - event-emitter - sqlmesh.core.analytics.dispatcher - INFO - Failed to emit events: HTTPSConnectionPool(host='analytics.tobikodata.com', port=443): Max retries exceeded with url: /v1/sqlmesh/ (Caused by SSLError(SSLCertVerificationError(1, '[SSL: CERTIFICATE_VERIFY_FAILED] certificate verify failed: self-signed certificate in certificate chain (_ssl.c:1006)'))) (dispatcher.py:138)
2025-03-11 17:44:43,398 - event-emitter - sqlmesh.core.analytics.dispatcher - INFO - Failed to emit events: HTTPSConnectionPool(host='analytics.tobikodata.com', port=443): Max retries exceeded with url: /v1/sqlmesh/ (Caused by SSLError(SSLCertVerificationError(1, '[SSL: CERTIFICATE_VERIFY_FAILED] certificate verify failed: self-signed certificate in certificate chain (_ssl.c:1006)'))) (dispatcher.py:138)
2025-03-11 17:44:48,529 - event-emitter - sqlmesh.core.analytics.dispatcher - INFO - Failed to emit events: HTTPSConnectionPool(host='analytics.tobikodata.com', port=443): Max retries exceeded with url: /v1/sqlmesh/ (Caused by SSLError(SSLCertVerificationError(1, '[SSL: CERTIFICATE_VERIFY_FAILED] certificate verify failed: self-signed certificate in certificate chain (_ssl.c:1006)'))) (dispatcher.py:138)
2025-03-11 17:44:49,873 - MainThread - snowflake.connector.vendored.urllib3.connectionpool - WARNING - Retrying (Retry(total=0, connect=None, read=None, redirect=None, status=None)) after connection broken by 'ConnectTimeoutError(<snowflake.connector.vendored.urllib3.connection.HTTPSConnection object at 0x000001F805C83F90>, 'Connection to ci54900.east-us-2.privatelink.snowflakecomputing.com timed out. (connect timeout=60)')': /session/v1/login-request?request_id=ea4192fd-af89-41a0-8ebf-44287a2d8b31&databaseName=DB_ADI_SQLMESH_DEV&warehouse=WH_ADI_SQMESH&roleName=ADI_IT_DATA_ENGINEER_FR&request_guid=64846f07-dcb5-4006-9709-cffc07f01cf1 (connectionpool.py:824)
2025-03-11 17:44:53,658 - event-emitter - sqlmesh.core.analytics.dispatcher - INFO - Failed to emit events: HTTPSConnectionPool(host='analytics.tobikodata.com', port=443): Max retries exceeded with url: /v1/sqlmesh/ (Caused by SSLError(SSLCertVerificationError(1, '[SSL: CERTIFICATE_VERIFY_FAILED] certificate verify failed: self-signed certificate in certificate chain (_ssl.c:1006)'))) (dispatcher.py:138)
2025-03-11 17:44:55,480 - MainThread - snowflake.connector.connection - INFO - closed (connection.py:810)
2025-03-11 17:44:55,638 - MainThread - snowflake.connector.connection - INFO - No async queries seem to be running, deleting session (connection.py:816)
2025-03-11 17:44:56,221 - MainThread - root - INFO - Shutting down the event dispatcher (dispatcher.py:159)
2025-03-11 17:44:56,347 - MainThread - sqlmesh.core.analytics.dispatcher - INFO - Failed to emit events: HTTPSConnectionPool(host='analytics.tobikodata.com', port=443): Max retries exceeded with url: /v1/sqlmesh/ (Caused by SSLError(SSLCertVerificationError(1, '[SSL: CERTIFICATE_VERIFY_FAILED] certificate verify failed: self-signed certificate in certificate chain (_ssl.c:1006)'))) (dispatcher.py:138)
