2025-03-11 17:26:57,010 - MainThread - sqlmesh.core.config.connection - INFO - Creating new DuckDB adapter for in-memory database (connection.py:318)
2025-03-11 17:26:57,010 - MainThread - sqlmesh.core.console - WARNING - Model '"DB_ADI_SQLMESH_DEV"."SQLMESH_EXAMPLE"."FULL_MODEL"' was not found at C:\SQLMESH_DEV\tests\test_full_model.yaml (console.py:1269)
2025-03-11 17:26:57,013 - MainThread - sqlmesh.core.console - WARNING - The snowflake engine is not recommended for storing SQLMesh state in production deployments. Please see https://sqlmesh.readthedocs.io/en/stable/guides/configuration/#state-connection for a list of recommended engines and more information. (console.py:1269)
2025-03-11 17:26:57,017 - MainThread - snowflake.connector.connection - INFO - Snowflake Connector for Python Version: 3.14.0, Python Version: 3.11.9, Platform: Windows-10-10.0.22621-SP0 (connection.py:423)
2025-03-11 17:26:57,017 - MainThread - snowflake.connector.connection - INFO - Connecting to GLOBAL Snowflake domain (connection.py:1226)
2025-03-11 17:26:57,017 - MainThread - snowflake.connector.connection - INFO - This connection is in OCSP Fail Open Mode. TLS Certificates would be checked for validity and revocation status. Any other Certificate Revocation related exceptions or OCSP Responder failures would be disregarded in favor of connectivity. (connection.py:1315)
2025-03-11 17:27:01,408 - event-emitter - sqlmesh.core.analytics.dispatcher - INFO - Failed to emit events: HTTPSConnectionPool(host='analytics.tobikodata.com', port=443): Max retries exceeded with url: /v1/sqlmesh/ (Caused by SSLError(SSLCertVerificationError(1, '[SSL: CERTIFICATE_VERIFY_FAILED] certificate verify failed: self-signed certificate in certificate chain (_ssl.c:1006)'))) (dispatcher.py:138)
2025-03-11 17:27:06,561 - event-emitter - sqlmesh.core.analytics.dispatcher - INFO - Failed to emit events: HTTPSConnectionPool(host='analytics.tobikodata.com', port=443): Max retries exceeded with url: /v1/sqlmesh/ (Caused by SSLError(SSLCertVerificationError(1, '[SSL: CERTIFICATE_VERIFY_FAILED] certificate verify failed: self-signed certificate in certificate chain (_ssl.c:1006)'))) (dispatcher.py:138)
2025-03-11 17:27:07,960 - ThreadPoolExecutor-11_0 - sqlmesh.core.snapshot.evaluator - INFO - Listing data objects in schema DB_ADI_SQLMESH_DEV.sqlmesh__SQLMESH (evaluator.py:323)
2025-03-11 17:27:07,960 - ThreadPoolExecutor-11_0 - snowflake.connector.connection - INFO - Snowflake Connector for Python Version: 3.14.0, Python Version: 3.11.9, Platform: Windows-10-10.0.22621-SP0 (connection.py:423)
2025-03-11 17:27:07,961 - ThreadPoolExecutor-11_0 - snowflake.connector.connection - INFO - Connecting to GLOBAL Snowflake domain (connection.py:1226)
2025-03-11 17:27:07,961 - ThreadPoolExecutor-11_0 - snowflake.connector.connection - INFO - This connection is in OCSP Fail Open Mode. TLS Certificates would be checked for validity and revocation status. Any other Certificate Revocation related exceptions or OCSP Responder failures would be disregarded in favor of connectivity. (connection.py:1315)
2025-03-11 17:27:08,793 - ThreadPoolExecutor-11_0 - sqlmesh.core.engine_adapter.base - INFO - Executing SQL: SELECT CURRENT_DATABASE() (base.py:2113)
2025-03-11 17:27:09,209 - ThreadPoolExecutor-11_0 - sqlmesh.core.engine_adapter.base - INFO - Executing SQL: SELECT CURRENT_DATABASE() (base.py:2113)
2025-03-11 17:27:09,709 - ThreadPoolExecutor-11_0 - sqlmesh.core.engine_adapter.base - INFO - Executing SQL: SELECT DISTINCT "TABLE_CATALOG" AS "catalog", "TABLE_NAME" AS "name", "TABLE_SCHEMA" AS "schema_name", CASE WHEN "TABLE_TYPE" = 'BASE TABLE' AND "IS_DYNAMIC" = 'YES' THEN 'MANAGED_TABLE' WHEN "TABLE_TYPE" = 'BASE TABLE' THEN 'TABLE' WHEN "TABLE_TYPE" = 'TEMPORARY TABLE' THEN 'TABLE' WHEN "TABLE_TYPE" = 'LOCAL TEMPORARY' THEN 'TABLE' WHEN "TABLE_TYPE" = 'EXTERNAL TABLE' THEN 'TABLE' WHEN "TABLE_TYPE" = 'EVENT TABLE' THEN 'TABLE' WHEN "TABLE_TYPE" = 'VIEW' THEN 'VIEW' WHEN "TABLE_TYPE" = 'MATERIALIZED VIEW' THEN 'MATERIALIZED_VIEW' ELSE "TABLE_TYPE" END AS "type", "CLUSTERING_KEY" AS "clustering_key" FROM "DB_ADI_SQLMESH_DEV"."INFORMATION_SCHEMA"."TABLES" WHERE "TABLE_SCHEMA" = 'sqlmesh__SQLMESH' AND "TABLE_NAME" IN ('SQLMESH__ORDER_STAGE__2493001244', 'SQLMESH__CUSTOMER_PROFIT__4259417223', 'SQLMESH__ORDER_PROFIT__417197957', 'SQLMESH__PRODUCT_STAGE__8161499', 'SQLMESH__CUSTOMER_STAGE__3527124355', 'SQLMESH__PRODUCT_PROFIT__136943708') (base.py:2113)
2025-03-11 17:27:10,740 - MainThread - snowflake.connector.connection - INFO - closed (connection.py:810)
2025-03-11 17:27:10,930 - MainThread - snowflake.connector.connection - INFO - No async queries seem to be running, deleting session (connection.py:816)
2025-03-11 17:27:11,484 - MainThread - sqlmesh.core.state_sync.db.facade - INFO - Promoting environment 'prod' (facade.py:165)
2025-03-11 17:27:11,660 - event-emitter - sqlmesh.core.analytics.dispatcher - INFO - Failed to emit events: HTTPSConnectionPool(host='analytics.tobikodata.com', port=443): Max retries exceeded with url: /v1/sqlmesh/ (Caused by SSLError(SSLCertVerificationError(1, '[SSL: CERTIFICATE_VERIFY_FAILED] certificate verify failed: self-signed certificate in certificate chain (_ssl.c:1006)'))) (dispatcher.py:138)
2025-03-11 17:27:16,828 - event-emitter - sqlmesh.core.analytics.dispatcher - INFO - Failed to emit events: HTTPSConnectionPool(host='analytics.tobikodata.com', port=443): Max retries exceeded with url: /v1/sqlmesh/ (Caused by SSLError(SSLCertVerificationError(1, '[SSL: CERTIFICATE_VERIFY_FAILED] certificate verify failed: self-signed certificate in certificate chain (_ssl.c:1006)'))) (dispatcher.py:138)
2025-03-11 17:27:20,955 - MainThread - sqlmesh.core.state_sync.db.snapshot - INFO - Unpausing snapshot SnapshotId<"DB_ADI_SQLMESH_DEV"."SQLMESH"."CUSTOMER_PROFIT": 2716878988> (snapshot.py:143)
2025-03-11 17:27:20,956 - MainThread - sqlmesh.core.state_sync.db.snapshot - INFO - Unpausing snapshot SnapshotId<"DB_ADI_SQLMESH_DEV"."SQLMESH"."PRODUCT_PROFIT": 1238932029> (snapshot.py:143)
2025-03-11 17:27:20,956 - MainThread - sqlmesh.core.state_sync.db.snapshot - INFO - Unpausing snapshot SnapshotId<"DB_ADI_SQLMESH_DEV"."SQLMESH"."CUSTOMER_STAGE": 2772891127> (snapshot.py:143)
2025-03-11 17:27:20,957 - MainThread - sqlmesh.core.state_sync.db.snapshot - INFO - Unpausing snapshot SnapshotId<"DB_ADI_SQLMESH_DEV"."SQLMESH"."ORDER_PROFIT": 2121590543> (snapshot.py:143)
2025-03-11 17:27:21,958 - event-emitter - sqlmesh.core.analytics.dispatcher - INFO - Failed to emit events: HTTPSConnectionPool(host='analytics.tobikodata.com', port=443): Max retries exceeded with url: /v1/sqlmesh/ (Caused by SSLError(SSLCertVerificationError(1, '[SSL: CERTIFICATE_VERIFY_FAILED] certificate verify failed: self-signed certificate in certificate chain (_ssl.c:1006)'))) (dispatcher.py:138)
2025-03-11 17:27:22,073 - MainThread - sqlmesh.core.snapshot.evaluator - INFO - Creating schema 'DB_ADI_SQLMESH_DEV.SQLMESH' (evaluator.py:1061)
2025-03-11 17:27:22,074 - MainThread - snowflake.connector.connection - INFO - Snowflake Connector for Python Version: 3.14.0, Python Version: 3.11.9, Platform: Windows-10-10.0.22621-SP0 (connection.py:423)
2025-03-11 17:27:22,074 - MainThread - snowflake.connector.connection - INFO - Connecting to GLOBAL Snowflake domain (connection.py:1226)
2025-03-11 17:27:22,074 - MainThread - snowflake.connector.connection - INFO - This connection is in OCSP Fail Open Mode. TLS Certificates would be checked for validity and revocation status. Any other Certificate Revocation related exceptions or OCSP Responder failures would be disregarded in favor of connectivity. (connection.py:1315)
2025-03-11 17:27:22,889 - MainThread - sqlmesh.core.engine_adapter.base - INFO - Executing SQL: CREATE SCHEMA IF NOT EXISTS "DB_ADI_SQLMESH_DEV"."SQLMESH" (base.py:2113)
2025-03-11 17:27:23,361 - ThreadPoolExecutor-25_0 - sqlmesh.core.snapshot.evaluator - INFO - Updating view 'DB_ADI_SQLMESH_DEV.SQLMESH.CUSTOMER_STAGE' to point at table 'DB_ADI_SQLMESH_DEV.sqlmesh__SQLMESH.SQLMESH__CUSTOMER_STAGE__3527124355' (evaluator.py:1368)
2025-03-11 17:27:23,363 - ThreadPoolExecutor-25_0 - snowflake.connector.connection - INFO - Snowflake Connector for Python Version: 3.14.0, Python Version: 3.11.9, Platform: Windows-10-10.0.22621-SP0 (connection.py:423)
2025-03-11 17:27:23,364 - ThreadPoolExecutor-25_0 - snowflake.connector.connection - INFO - Connecting to GLOBAL Snowflake domain (connection.py:1226)
2025-03-11 17:27:23,364 - ThreadPoolExecutor-25_0 - snowflake.connector.connection - INFO - This connection is in OCSP Fail Open Mode. TLS Certificates would be checked for validity and revocation status. Any other Certificate Revocation related exceptions or OCSP Responder failures would be disregarded in favor of connectivity. (connection.py:1315)
2025-03-11 17:27:24,101 - ThreadPoolExecutor-25_0 - sqlmesh.core.engine_adapter.base - INFO - Executing SQL: CREATE OR REPLACE VIEW "DB_ADI_SQLMESH_DEV"."SQLMESH"."CUSTOMER_STAGE" COPY GRANTS AS SELECT * FROM "DB_ADI_SQLMESH_DEV"."sqlmesh__SQLMESH"."SQLMESH__CUSTOMER_STAGE__3527124355" (base.py:2113)
2025-03-11 17:27:25,107 - ThreadPoolExecutor-25_1 - sqlmesh.core.snapshot.evaluator - INFO - Updating view 'DB_ADI_SQLMESH_DEV.SQLMESH.ORDER_PROFIT' to point at table 'DB_ADI_SQLMESH_DEV.sqlmesh__SQLMESH.SQLMESH__ORDER_PROFIT__417197957' (evaluator.py:1368)
2025-03-11 17:27:25,108 - ThreadPoolExecutor-25_1 - snowflake.connector.connection - INFO - Snowflake Connector for Python Version: 3.14.0, Python Version: 3.11.9, Platform: Windows-10-10.0.22621-SP0 (connection.py:423)
2025-03-11 17:27:25,109 - ThreadPoolExecutor-25_1 - snowflake.connector.connection - INFO - Connecting to GLOBAL Snowflake domain (connection.py:1226)
2025-03-11 17:27:25,109 - ThreadPoolExecutor-25_1 - snowflake.connector.connection - INFO - This connection is in OCSP Fail Open Mode. TLS Certificates would be checked for validity and revocation status. Any other Certificate Revocation related exceptions or OCSP Responder failures would be disregarded in favor of connectivity. (connection.py:1315)
2025-03-11 17:27:25,957 - ThreadPoolExecutor-25_1 - sqlmesh.core.engine_adapter.base - INFO - Executing SQL: CREATE OR REPLACE VIEW "DB_ADI_SQLMESH_DEV"."SQLMESH"."ORDER_PROFIT" COPY GRANTS AS SELECT * FROM "DB_ADI_SQLMESH_DEV"."sqlmesh__SQLMESH"."SQLMESH__ORDER_PROFIT__417197957" (base.py:2113)
2025-03-11 17:27:27,077 - event-emitter - sqlmesh.core.analytics.dispatcher - INFO - Failed to emit events: HTTPSConnectionPool(host='analytics.tobikodata.com', port=443): Max retries exceeded with url: /v1/sqlmesh/ (Caused by SSLError(SSLCertVerificationError(1, '[SSL: CERTIFICATE_VERIFY_FAILED] certificate verify failed: self-signed certificate in certificate chain (_ssl.c:1006)'))) (dispatcher.py:138)
2025-03-11 17:27:27,221 - ThreadPoolExecutor-25_0 - sqlmesh.core.snapshot.evaluator - INFO - Updating view 'DB_ADI_SQLMESH_DEV.SQLMESH.CUSTOMER_PROFIT' to point at table 'DB_ADI_SQLMESH_DEV.sqlmesh__SQLMESH.SQLMESH__CUSTOMER_PROFIT__4259417223' (evaluator.py:1368)
2025-03-11 17:27:27,223 - ThreadPoolExecutor-25_0 - sqlmesh.core.engine_adapter.base - INFO - Executing SQL: CREATE OR REPLACE VIEW "DB_ADI_SQLMESH_DEV"."SQLMESH"."CUSTOMER_PROFIT" COPY GRANTS AS SELECT * FROM "DB_ADI_SQLMESH_DEV"."sqlmesh__SQLMESH"."SQLMESH__CUSTOMER_PROFIT__4259417223" (base.py:2113)
2025-03-11 17:27:27,225 - ThreadPoolExecutor-25_2 - sqlmesh.core.snapshot.evaluator - INFO - Updating view 'DB_ADI_SQLMESH_DEV.SQLMESH.PRODUCT_PROFIT' to point at table 'DB_ADI_SQLMESH_DEV.sqlmesh__SQLMESH.SQLMESH__PRODUCT_PROFIT__136943708' (evaluator.py:1368)
2025-03-11 17:27:27,227 - ThreadPoolExecutor-25_2 - snowflake.connector.connection - INFO - Snowflake Connector for Python Version: 3.14.0, Python Version: 3.11.9, Platform: Windows-10-10.0.22621-SP0 (connection.py:423)
2025-03-11 17:27:27,227 - ThreadPoolExecutor-25_2 - snowflake.connector.connection - INFO - Connecting to GLOBAL Snowflake domain (connection.py:1226)
2025-03-11 17:27:27,228 - ThreadPoolExecutor-25_2 - snowflake.connector.connection - INFO - This connection is in OCSP Fail Open Mode. TLS Certificates would be checked for validity and revocation status. Any other Certificate Revocation related exceptions or OCSP Responder failures would be disregarded in favor of connectivity. (connection.py:1315)
2025-03-11 17:27:27,941 - ThreadPoolExecutor-25_2 - sqlmesh.core.engine_adapter.base - INFO - Executing SQL: CREATE OR REPLACE VIEW "DB_ADI_SQLMESH_DEV"."SQLMESH"."PRODUCT_PROFIT" COPY GRANTS AS SELECT * FROM "DB_ADI_SQLMESH_DEV"."sqlmesh__SQLMESH"."SQLMESH__PRODUCT_PROFIT__136943708" (base.py:2113)
2025-03-11 17:27:28,865 - MainThread - snowflake.connector.connection - INFO - closed (connection.py:810)
2025-03-11 17:27:29,021 - MainThread - snowflake.connector.connection - INFO - No async queries seem to be running, deleting session (connection.py:816)
2025-03-11 17:27:29,211 - MainThread - snowflake.connector.connection - INFO - closed (connection.py:810)
2025-03-11 17:27:29,368 - MainThread - snowflake.connector.connection - INFO - No async queries seem to be running, deleting session (connection.py:816)
2025-03-11 17:27:29,543 - MainThread - snowflake.connector.connection - INFO - closed (connection.py:810)
2025-03-11 17:27:29,705 - MainThread - snowflake.connector.connection - INFO - No async queries seem to be running, deleting session (connection.py:816)
2025-03-11 17:27:29,895 - MainThread - sqlmesh.core.state_sync.db.environment - INFO - Finalizing environment 'prod' (environment.py:135)
2025-03-11 17:27:31,333 - MainThread - snowflake.connector.connection - INFO - closed (connection.py:810)
2025-03-11 17:27:31,490 - MainThread - snowflake.connector.connection - INFO - No async queries seem to be running, deleting session (connection.py:816)
2025-03-11 17:27:31,684 - MainThread - snowflake.connector.connection - INFO - closed (connection.py:810)
2025-03-11 17:27:31,846 - MainThread - snowflake.connector.connection - INFO - No async queries seem to be running, deleting session (connection.py:816)
2025-03-11 17:27:32,024 - MainThread - root - INFO - Shutting down the event dispatcher (dispatcher.py:159)
2025-03-11 17:27:32,221 - MainThread - sqlmesh.core.analytics.dispatcher - INFO - Failed to emit events: HTTPSConnectionPool(host='analytics.tobikodata.com', port=443): Max retries exceeded with url: /v1/sqlmesh/ (Caused by SSLError(SSLCertVerificationError(1, '[SSL: CERTIFICATE_VERIFY_FAILED] certificate verify failed: self-signed certificate in certificate chain (_ssl.c:1006)'))) (dispatcher.py:138)
